<?xml version="1.0"?>
<!-- Open_Manipulator Chain -->
<robot xmlns:xacro="http://ros.org/wiki/xacro">

  <!-- Link 1 -->
  <link name="link1">
    <visual>
      <origin xyz="${0.059*0.5} 0.0 ${0.050*0.5}" rpy="0 0 0"/>
      <geometry>
        <box size="0.059 0.031 0.050"/>
      </geometry>
      <material name="grey"/>
    </visual>

    <collision>
      <origin xyz="${0.059*0.5} 0.0 ${0.050*0.5}" rpy="0 0 0"/>
      <geometry>
        <box size="0.059 0.031 0.045"/>
      </geometry>
    </collision>

    <inertial>
      <origin xyz="3.0876154e-04 0.0000000e+00 -1.2176461e-04" />
      <mass value="7.9119962e-02" />
      <inertia ixx="1.2505234e-05" ixy="0.0" ixz="-1.7855208e-07"
               iyy="2.1898364e-05" iyz="0.0"
               izz="1.9267361e-05" />
    </inertial>
  </link>

  <!-- Joint 1 -->
  <joint name="joint1" type="revolute">
    <parent link="link1"/>
    <child link="link2"/>
    <origin xyz="0.045 0.0 0.050" rpy="0 0 0"/>
    <axis xyz="0 0 1"/>
    <limit velocity="4.8" effort="1" lower="${-pi*0.9}" upper="${pi*0.9}" />
  </joint>

  <!--  Link 2 -->
  <link name="link2">
    <visual>
      <origin xyz="0.0 0.0 ${0.065*0.5}" rpy="0 0 0"/>
      <geometry>
        <box size="0.033 0.048 0.065"/>
      </geometry>
      <material name="grey"/>
    </visual>

    <collision>
      <origin xyz="0.0 0.0 ${0.065*0.5}" rpy="0 0 0"/>
      <geometry>
        <box size="0.033 0.048 0.060"/>
      </geometry>
    </collision>

    <inertial>
      <origin xyz="-3.0184870e-04 5.4043684e-04 ${0.018 + 2.9433464e-02}" />
      <mass value="9.8406837e-02" />
      <inertia ixx="3.4543422e-05" ixy="-1.6031095e-08" ixz="-3.8375155e-07"
               iyy="3.2689329e-05" iyz="2.8511935e-08"
               izz="1.8850320e-05" />
    </inertial>
  </link>

  <!--  Joint 2 -->
  <joint name="joint2" type="revolute">
    <parent link="link2"/>
    <child link="link3"/>
    <origin xyz="0.0 0.0 0.050" rpy="0 0 ${pi}"/>
    <axis xyz="0 1 0"/>
    <limit velocity="4.8" effort="1" lower="-2.8" upper="2.8" />
  </joint>

  <!--  Link 3 -->
  <link name="link3">
    <visual>
      <origin xyz="0 0 ${0.080*0.5}" rpy="0 0 0"/>
      <geometry>
        <box size="0.030 0.033 0.080"/>
      </geometry>
      <material name="grey"/>
    </visual>

    <collision>
      <origin xyz="0 0 ${0.080*0.5}" rpy="0 0 0"/>
      <geometry>
        <box size="0.030 0.033 0.075"/>
      </geometry>
    </collision>

    <inertial>
      <origin xyz="1.0308393e-02 3.7743363e-04 1.0170197e-01" />
      <mass value="1.3850917e-01" />
      <inertia ixx="3.3055381e-04" ixy="-9.7940978e-08" ixz="-3.8505711e-05"
               iyy="3.4290447e-04" iyz="-1.5717516e-06"
               izz="6.0346498e-05" />
    </inertial>
  </link>

  <!--  Joint 3 -->
  <joint name="joint3" type="revolute">
    <parent link="link3"/>
    <child link="link4"/>
    <origin xyz="0 0 0.0675" rpy="0 ${-pi*0.5} 0"/>
    <axis xyz="0 1 0"/>
    <limit velocity="4.8" effort="1" lower="-2.8" upper="2.8" />
  </joint>

  <!--  Link 4 -->
  <link name="link4">
    <visual>
      <origin xyz="0 0 0" rpy="0 0 0"/>
      <geometry>
        <mesh filename="package://open_manipulator_description/meshes/chain_link4.stl" scale="0.001 0.001 0.001"/>
      </geometry>
      <material name="grey"/>
    </visual>

    <collision>
      <origin xyz="0 0 0" rpy="0 0 0"/>
      <geometry>
        <mesh filename="package://open_manipulator_description/meshes/chain_link4.stl" scale="0.001 0.001 0.001"/>
      </geometry>
    </collision>

    <inertial>
      <origin xyz="9.0909590e-02 3.8929816e-04 2.2413279e-04" />
      <mass value="1.3274562e-01" />
      <inertia ixx="3.0654178e-05" ixy="-1.2764155e-06" ixz="-2.6874417e-07"
               iyy="2.4230292e-04" iyz="1.1559550e-08"
               izz="2.5155057e-04" />
    </inertial>
  </link>

  <!--  Joint 4 -->
  <joint name="joint4" type="revolute">
    <parent link="link4"/>
    <child link="link5"/>
    <origin xyz="0.124 0.0 0.0" rpy="0 0 0"/>
    <axis xyz="0 1 0"/>
    <limit velocity="4.8" effort="1" lower="-2.8" upper="2.8" />
  </joint>

  <!--  Link 5 -->
  <link name="link5">
    <visual>
      <origin xyz="${0.075*0.5} 0 0" rpy="0 0 0"/>
      <geometry>
        <box size="0.075 0.04 0.047"/>
      </geometry>
      <material name="grey"/>
    </visual>

    <collision>
      <origin xyz="${0.075*0.5} 0 0" rpy="0 0 0"/>
      <geometry>
        <box size="0.070 0.04 0.047"/>
      </geometry>
    </collision>

    <inertial>
      <origin xyz="4.4206755e-02 3.6839985e-07 8.9142216e-03" />
      <mass value="1.4327573e-01" />
      <inertia ixx="8.0870749e-05" ixy="0.0" ixz="-1.0157896e-06"
               iyy="7.5980465e-05" iyz="0.0"
               izz="9.3127351e-05" />
    </inertial>
  </link>

  <!--  Joint 5 -->
  <joint name="joint5" type="revolute">
    <parent link="link5"/>
    <child link="link6"/>
    <origin xyz="0.062 0.0 0.0165" rpy="0 0 0"/>
    <axis xyz="0 0 1"/>
    <limit velocity="4.8" effort="1" lower="-2.8" upper="2.8" />
  </joint>

  <!--  Link 6 -->
  <link name="link6">
    <visual>
      <origin xyz="${0.067*0.5} 0 0" rpy="0 0 0"/>
      <geometry>
        <box size="0.067 0.03 0.045"/>
      </geometry>
      <material name="grey"/>
    </visual>

    <collision>
      <origin xyz="${0.067*0.5} 0 0" rpy="0 0 0"/>
      <geometry>
        <box size="0.062 0.03 0.045"/>
      </geometry>
    </collision>

    <inertial>
      <origin xyz="4.4206755e-02 3.6839985e-07 8.9142216e-03" />
      <mass value="1.4327573e-01" />
      <inertia ixx="8.0870749e-05" ixy="0.0" ixz="-1.0157896e-06"
               iyy="7.5980465e-05" iyz="0.0"
               izz="9.3127351e-05" />
    </inertial>
  </link>

  <!--  Joint 6 -->
  <joint name="joint6" type="revolute">
    <parent link="link6"/>
    <child link="end_effector"/>
    <origin xyz="0.07 0 -0.012" rpy="0 0 0"/>
    <axis xyz="1 0 0"/>
    <limit velocity="4.8" effort="1" lower="${-pi*0.9}" upper="${pi*0.9}" />
  </joint>

  <!-- end effector-->
  <link name="end_effector">
    <visual>
      <origin xyz="${0.165*0.5} 0 0" rpy="0 0 0"/>
      <geometry>
        <box size="0.165 0.005 0.005" />
      </geometry>
      <material name="white"/>
     </visual>

    <inertial>
      <origin xyz="0 0 0" />
      <mass value="1.0e-03" />
      <inertia ixx="1.0e-03" ixy="0.0" ixz="0.0"
               iyy="1.0e-03" iyz="0.0"
               izz="1.0e-03" />
    </inertial>
  </link>  
</robot>
